Workbook

Sheet Instructions
B2: Masrur Supply Chain Analytics
B3: Supply Chain Business Review — Interactive Dashboard
B5: OVERVIEW
B6: This workbook is a fully formula-driven, interactive supply chain dashboard. Every KPI, chart and summary refreshes automatically when you change the slicer cells on the Dashboard tab. No VBA, no macros — only Excel Tables, structured references, SUMIFS / COUNTIFS / AVERAGEIFS / XLOOKUP, and Data Validation dropdowns.
B8: SOURCE TABS (DATA)
B9: Tab | C9: Excel Table | D9: What it contains
B10: Parts_Master | C10: tblParts | D10: 20 parts: ID, name, supplier, lead time, unit cost, multi-source flag, sourcing risk
B11: Demand_Forecast | C11: tblForecast | D11: ~1,560 weekly forecast vs actual rows by Program × Part
B12: Inventory_Coverage | C12: tblInventory | D12: 80 part × region rows: on-hand, on-order, burn rate, coverage, shortage risk
B13: Purchase_Orders | C13: tblPO | D13: 350 POs: supplier, factory, region, dates, status, on-time flag, total value
B14: NPI_Program_Tracker | C14: tblNPI | D14: 120 milestones across 5 programs × 4 regions × 6 milestones
B15: Supplier_Scorecard | C15: tblSupplier | D15: 16 suppliers: OTD%, quality PPM, lead-time adherence, spend, risk rating
B17: KPI DEFINITIONS
B18: KPI | C18: What it measures | D18: How it is calculated
B19: Forecast Accuracy % | C19: How close weekly forecasts came to actual demand | D19: 1 − ( SUM(|Actual − Forecast|) / SUM(Actual) ) over the selected Program & Region scope
B20: On-Time Delivery % | C20: Share of POs received on or before need-by date | D20: COUNTIFS(On_Time=TRUE) / COUNTIFS(all POs) within the slicer scope
B21: Avg Days Late | C21: Average delay on POs that slipped | D21: AVERAGEIFS(Days_Late, Days_Late, ">0") in scope
B22: Open PO Value ($M) | C22: Dollars at risk in open / in-transit / delayed POs | D22: SUMIFS(Total_Value, Status, “not Goods Received”) / 1,000,000
B23: Critical+High Shortage Lines | C23: Count of part × region inventory positions flagged Critical or High | D23: COUNTIFS(Shortage_Risk ∈ {CRITICAL, HIGH}) in scope
B24: Clean Launch % | C24: Share of NPI program-region rows that hit a clean launch | D24: COUNTIFS(Clean_Launch=TRUE) / COUNTIFS(all) in scope
B25: Multi-Source Coverage % | C25: Share of parts that have more than one qualified supplier | D25: COUNTIF(tblParts[Multi_Source], TRUE) / COUNTA(tblParts[Part_ID])
B27: FORMULAS & TECHNIQUES USED
B28: Technique | C28: Where | D28: Why
B29: Excel Tables + Structured References (e.g. tblPO[Total_Value_USD]) | C29: All source tabs | D29: Ranges auto-expand when you append data — no broken formulas
B30: Data Validation (List) | C30: Dashboard!C5 (Region), Dashboard!C6 (Program) | D30: Creates the dropdown slicers that drive every KPI and chart
B31: SUMIFS / COUNTIFS / AVERAGEIFS with wildcard ("*") | C31: KPI cards & helper tables | D31: A slicer set to “All” passes “*” as the criterion so every row matches
B32: IFERROR wrapper | C32: Every ratio / percentage KPI | D32: Returns 0 instead of #DIV/0! when a slicer combination has no rows
B33: XLOOKUP | C33: Top suppliers table | D33: Pulls supplier metrics by name without hard-coded row numbers
B34: LARGE + INDEX/MATCH (ranking) | C34: Top 5 / Bottom 5 lists | D34: Dynamically ranks suppliers / parts by metric without sorting source
B35: Conditional Formatting (data bars, color scales) | C35: KPI cards, ranking tables | D35: Modern visual cues without extra columns
B37: HOW TO USE
B38: 1. Open the Dashboard tab.
B39: 2. Use the two yellow slicer cells at the top — Region (All / NAM / EMEA / APJ / BRH) and Program (All / Program A…E).
B40: 3. Every KPI card, ranking table and chart recalculates instantly.
B41: 4. To add new data: paste new rows directly under any source table — the table will auto-expand and the dashboard will pick it up.
B42: 5. To replicate this manually: build the 6 source tables, add Instructions & Dashboard sheets, drop the slicer cells with Data Validation, then write the SUMIFS / COUNTIFS / AVERAGEIFS formulas on the Dashboard pointing at the structured-reference columns.
B44: NOTES
B45: • No VBA, no macros — 100% native Excel formulas, tables and conditional formatting.
B46: • Nothing is hard-coded — every KPI cell points back to a source table column via structured references.
B47: • Program names (A–E) and Supplier names (1–16) are anonymized placeholders, safe for external demo use.

Sheet Dashboard
AB1: Slicer Helpers (used by formulas)
B2: Masrur Supply Chain Analytics | AB2: Region criterion | AC2: =IF(D5="All","*",D5) -> *
B3: Supply Chain Business Review • Interactive Demo Dashboard | AB3: Program criterion | AC3: =IF(H5="All","*",H5) -> *
B5: REGION | D5: All | F5: PROGRAM | H5: All | J5: Tip: change either dropdown — every KPI & chart updates instantly. | AB5: Region list | AD5: Program list
AB6: All | AD6: All
B7: FORECAST ACCURACY | F7: ON-TIME DELIVERY | J7: AVG DAYS LATE | AB7: NAM | AD7: Program A
B8: {=IFERROR(1-SUMPRODUCT(ABS(tblForecast[Variance])*(IF($AC$3="*",1,--(tblForecast[Program]=$AC$3))))/SUMIFS(tblForecast[Actual_Demand],tblForecast[Program],$AC$3),0)} -> 0.85531742 | F8: =IFERROR(COUNTIFS(tblPO[On_Time],TRUE,tblPO[Region],$AC$2)/COUNTIFS(tblPO[Region],$AC$2),0) -> 0.80571429 | J8: =IFERROR(AVERAGEIFS(tblPO[Days_Late],tblPO[Days_Late],">0",tblPO[Region],$AC$2),0) -> 19.397059 | AB8: EMEA | AD8: Program B
B9: Weekly forecast vs actual demand variance | F9: POs received on/before need-by date | J9: Average slip on POs that ran late | AB9: APJ | AD9: Program C
AB10: BRH | AD10: Program D
AD11: Program E
B12: OPEN PO VALUE | F12: SHORTAGE ALERTS | J12: CLEAN LAUNCH %
B13: =(SUMIFS(tblPO[Total_Value_USD],tblPO[Status],"Open",tblPO[Region],$AC$2)+SUMIFS(tblPO[Total_Value_USD],tblPO[Status],"In Transit",tblPO[Region],$AC$2)+SUMIFS(tblPO[Total_Value_USD],tblPO[Status],"Delayed",tblPO[Region],$AC$2))/1000000 -> 28.388557 | F13: =COUNTIFS(tblInventory[Shortage_Risk],"CRITICAL",tblInventory[Region],$AC$2)+COUNTIFS(tblInventory[Shortage_Risk],"HIGH",tblInventory[Region],$AC$2) -> 41 | J13: =IFERROR(COUNTIFS(tblNPI[Clean_Launch],TRUE,tblNPI[Program],$AC$3,tblNPI[Region],$AC$2)/COUNTIFS(tblNPI[Program],$AC$3,tblNPI[Region],$AC$2),0) -> 0.875 | AB13: HELPER: Forecast vs Actual by Month
B14: Dollars in-flight (Open / In Transit / Delayed) | F14: Critical + High shortage positions | J14: NPI milestones hitting a clean launch | AB14: Month | AC14: Forecast | AD14: Actual
AB15: 2025-01 | AC15: {=SUMPRODUCT((TEXT(tblForecast[Week],"yyyy-mm")=$AB15)*(IF($AC$3="*",1,--(tblForecast[Program]=$AC$3)))*tblForecast[Forecast_Qty])} -> 6472 | AD15: {=SUMPRODUCT((TEXT(tblForecast[Week],"yyyy-mm")=$AB15)*(IF($AC$3="*",1,--(tblForecast[Program]=$AC$3)))*tblForecast[Actual_Demand])} -> 6393
AB16: 2025-02 | AC16: {=SUMPRODUCT((TEXT(tblForecast[Week],"yyyy-mm")=$AB16)*(IF($AC$3="*",1,--(tblForecast[Program]=$AC$3)))*tblForecast[Forecast_Qty])} -> 7472 | AD16: {=SUMPRODUCT((TEXT(tblForecast[Week],"yyyy-mm")=$AB16)*(IF($AC$3="*",1,--(tblForecast[Program]=$AC$3)))*tblForecast[Actual_Demand])} -> 7472
B17: DEMAND — Forecast vs Actual (monthly) | H17: PROCUREMENT — Purchase Order status | AB17: 2025-03 | AC17: {=SUMPRODUCT((TEXT(tblForecast[Week],"yyyy-mm")=$AB17)*(IF($AC$3="*",1,--(tblForecast[Program]=$AC$3)))*tblForecast[Forecast_Qty])} -> 10435 | AD17: {=SUMPRODUCT((TEXT(tblForecast[Week],"yyyy-mm")=$AB17)*(IF($AC$3="*",1,--(tblForecast[Program]=$AC$3)))*tblForecast[Actual_Demand])} -> 10660
AB18: 2025-04 | AC18: {=SUMPRODUCT((TEXT(tblForecast[Week],"yyyy-mm")=$AB18)*(IF($AC$3="*",1,--(tblForecast[Program]=$AC$3)))*tblForecast[Forecast_Qty])} -> 9509 | AD18: {=SUMPRODUCT((TEXT(tblForecast[Week],"yyyy-mm")=$AB18)*(IF($AC$3="*",1,--(tblForecast[Program]=$AC$3)))*tblForecast[Actual_Demand])} -> 9409
AB19: 2025-05 | AC19: {=SUMPRODUCT((TEXT(tblForecast[Week],"yyyy-mm")=$AB19)*(IF($AC$3="*",1,--(tblForecast[Program]=$AC$3)))*tblForecast[Forecast_Qty])} -> 10428 | AD19: {=SUMPRODUCT((TEXT(tblForecast[Week],"yyyy-mm")=$AB19)*(IF($AC$3="*",1,--(tblForecast[Program]=$AC$3)))*tblForecast[Actual_Demand])} -> 10055
AB20: 2025-06 | AC20: {=SUMPRODUCT((TEXT(tblForecast[Week],"yyyy-mm")=$AB20)*(IF($AC$3="*",1,--(tblForecast[Program]=$AC$3)))*tblForecast[Forecast_Qty])} -> 14408 | AD20: {=SUMPRODUCT((TEXT(tblForecast[Week],"yyyy-mm")=$AB20)*(IF($AC$3="*",1,--(tblForecast[Program]=$AC$3)))*tblForecast[Actual_Demand])} -> 12888
AB21: 2025-07 | AC21: {=SUMPRODUCT((TEXT(tblForecast[Week],"yyyy-mm")=$AB21)*(IF($AC$3="*",1,--(tblForecast[Program]=$AC$3)))*tblForecast[Forecast_Qty])} -> 12403 | AD21: {=SUMPRODUCT((TEXT(tblForecast[Week],"yyyy-mm")=$AB21)*(IF($AC$3="*",1,--(tblForecast[Program]=$AC$3)))*tblForecast[Actual_Demand])} -> 12241
AB22: 2025-08 | AC22: {=SUMPRODUCT((TEXT(tblForecast[Week],"yyyy-mm")=$AB22)*(IF($AC$3="*",1,--(tblForecast[Program]=$AC$3)))*tblForecast[Forecast_Qty])} -> 13469 | AD22: {=SUMPRODUCT((TEXT(tblForecast[Week],"yyyy-mm")=$AB22)*(IF($AC$3="*",1,--(tblForecast[Program]=$AC$3)))*tblForecast[Actual_Demand])} -> 13137
AB23: 2025-09 | AC23: {=SUMPRODUCT((TEXT(tblForecast[Week],"yyyy-mm")=$AB23)*(IF($AC$3="*",1,--(tblForecast[Program]=$AC$3)))*tblForecast[Forecast_Qty])} -> 18079 | AD23: {=SUMPRODUCT((TEXT(tblForecast[Week],"yyyy-mm")=$AB23)*(IF($AC$3="*",1,--(tblForecast[Program]=$AC$3)))*tblForecast[Actual_Demand])} -> 18256
AB24: 2025-10 | AC24: {=SUMPRODUCT((TEXT(tblForecast[Week],"yyyy-mm")=$AB24)*(IF($AC$3="*",1,--(tblForecast[Program]=$AC$3)))*tblForecast[Forecast_Qty])} -> 15380 | AD24: {=SUMPRODUCT((TEXT(tblForecast[Week],"yyyy-mm")=$AB24)*(IF($AC$3="*",1,--(tblForecast[Program]=$AC$3)))*tblForecast[Actual_Demand])} -> 15186
AB25: 2025-11 | AC25: {=SUMPRODUCT((TEXT(tblForecast[Week],"yyyy-mm")=$AB25)*(IF($AC$3="*",1,--(tblForecast[Program]=$AC$3)))*tblForecast[Forecast_Qty])} -> 15303 | AD25: {=SUMPRODUCT((TEXT(tblForecast[Week],"yyyy-mm")=$AB25)*(IF($AC$3="*",1,--(tblForecast[Program]=$AC$3)))*tblForecast[Actual_Demand])} -> 15476
AB26: 2025-12 | AC26: {=SUMPRODUCT((TEXT(tblForecast[Week],"yyyy-mm")=$AB26)*(IF($AC$3="*",1,--(tblForecast[Program]=$AC$3)))*tblForecast[Forecast_Qty])} -> 19153 | AD26: {=SUMPRODUCT((TEXT(tblForecast[Week],"yyyy-mm")=$AB26)*(IF($AC$3="*",1,--(tblForecast[Program]=$AC$3)))*tblForecast[Actual_Demand])} -> 19163
AB28: HELPER: PO Status mix
AB29: Status | AC29: Count
AB30: Open | AC30: =COUNTIFS(tblPO[Status],$AB30,tblPO[Region],$AC$2) -> 80
AB31: In Transit | AC31: =COUNTIFS(tblPO[Status],$AB31,tblPO[Region],$AC$2) -> 104
B32: TOP 5 SUPPLIERS — On-Time Delivery | H32: TOP 5 PARTS AT RISK — Lowest Coverage | AB32: Delayed | AC32: =COUNTIFS(tblPO[Status],$AB32,tblPO[Region],$AC$2) -> 68
B33: Rank | C33: Supplier | D33: OTD % | E33: Spend ($M) | F33: Risk | H33: Part ID | I33: Part Name | J33: Region | K33: On Hand | L33: Coverage | M33: Risk | AB33: Goods Received | AC33: =COUNTIFS(tblPO[Status],$AB33,tblPO[Region],$AC$2) -> 98
B34: =AB44 -> 1 | C34: =AC44 -> Supplier 13 | D34: =AD44 -> 0.961 | E34: =AE44 -> 20.38 | F34: =AF44 -> MEDIUM | H34: =AD70 -> P1002 | I34: =AE70 -> SSD | J34: =AF70 -> BRH | K34: =AG70 -> 20 | L34: =AC70 -> 0.3 | M34: =AH70 -> CRITICAL
B35: =AB45 -> 2 | C35: =AC45 -> Supplier 4 | D35: =AD45 -> 0.951 | E35: =AE45 -> 5.58 | F35: =AF45 -> MEDIUM | H35: =AD71 -> P1017 | I35: =AE71 -> LCD Bezel | J35: =AF71 -> APJ | K35: =AG71 -> 23 | L35: =AC71 -> 0.3 | M35: =AH71 -> CRITICAL | AB35: HELPER: Shortage Risk by Region
B36: =AB46 -> 3 | C36: =AC46 -> Supplier 2 | D36: =AD46 -> 0.916 | E36: =AE46 -> 20.81 | F36: =AF46 -> HIGH | H36: =AD72 -> P1017 | I36: =AE72 -> LCD Bezel | J36: =AF72 -> EMEA | K36: =AG72 -> 8 | L36: =AC72 -> 0.5 | M36: =AH72 -> CRITICAL | AB36: Region | AC36: Low | AD36: Medium | AE36: High | AF36: Critical
B37: =AB47 -> 4 | C37: =AC47 -> Supplier 1 | D37: =AD47 -> 0.914 | E37: =AE47 -> 3.47 | F37: =AF47 -> LOW | H37: =AD73 -> P1016 | I37: =AE73 -> Luggage Tag Kit | J37: =AF73 -> NAM | K37: =AG73 -> 43 | L37: =AC73 -> 1.2 | M37: =AH73 -> CRITICAL | AB37: NAM | AC37: =COUNTIFS(tblInventory[Region],$AB37,tblInventory[Shortage_Risk],"LOW") -> 7 | AD37: =COUNTIFS(tblInventory[Region],$AB37,tblInventory[Shortage_Risk],"MEDIUM") -> 5 | AE37: =COUNTIFS(tblInventory[Region],$AB37,tblInventory[Shortage_Risk],"HIGH") -> 6 | AF37: =COUNTIFS(tblInventory[Region],$AB37,tblInventory[Shortage_Risk],"CRITICAL") -> 2
B38: =AB48 -> 5 | C38: =AC48 -> Supplier 9 | D38: =AD48 -> 0.911 | E38: =AE48 -> 22.82 | F38: =AF48 -> MEDIUM | H38: =AD74 -> P1015 | I38: =AE74 -> Luggage Tag Kit | J38: =AF74 -> APJ | K38: =AG74 -> 76 | L38: =AC74 -> 2 | M38: =AH74 -> CRITICAL | AB38: EMEA | AC38: =COUNTIFS(tblInventory[Region],$AB38,tblInventory[Shortage_Risk],"LOW") -> 3 | AD38: =COUNTIFS(tblInventory[Region],$AB38,tblInventory[Shortage_Risk],"MEDIUM") -> 4 | AE38: =COUNTIFS(tblInventory[Region],$AB38,tblInventory[Shortage_Risk],"HIGH") -> 12 | AF38: =COUNTIFS(tblInventory[Region],$AB38,tblInventory[Shortage_Risk],"CRITICAL") -> 1
AB39: APJ | AC39: =COUNTIFS(tblInventory[Region],$AB39,tblInventory[Shortage_Risk],"LOW") -> 6 | AD39: =COUNTIFS(tblInventory[Region],$AB39,tblInventory[Shortage_Risk],"MEDIUM") -> 7 | AE39: =COUNTIFS(tblInventory[Region],$AB39,tblInventory[Shortage_Risk],"HIGH") -> 3 | AF39: =COUNTIFS(tblInventory[Region],$AB39,tblInventory[Shortage_Risk],"CRITICAL") -> 4
B40: INVENTORY — Shortage Risk by Region | H40: SUPPLIERS — On-Time Delivery ranking | AB40: BRH | AC40: =COUNTIFS(tblInventory[Region],$AB40,tblInventory[Shortage_Risk],"LOW") -> 2 | AD40: =COUNTIFS(tblInventory[Region],$AB40,tblInventory[Shortage_Risk],"MEDIUM") -> 5 | AE40: =COUNTIFS(tblInventory[Region],$AB40,tblInventory[Shortage_Risk],"HIGH") -> 12 | AF40: =COUNTIFS(tblInventory[Region],$AB40,tblInventory[Shortage_Risk],"CRITICAL") -> 1
AB42: HELPER: Supplier OTD ranking (sorted desc)
AB43: Rank | AC43: Supplier | AD43: OTD % | AE43: Spend $M | AF43: Risk
...

Sheet Parts_Master
A1: Part_ID | B1: Part_Name | C1: Supplier | D1: Lead_Time_Weeks | E1: Unit_Cost_USD | F1: Multi_Source | G1: Sourcing_Risk
A2: P1000 | B2: GPU | C2: Supplier 13 | D2: 19 | E2: 2976 | F2: TRUE | G2: MEDIUM
A3: P1001 | B3: GPU | C3: Supplier 1 | D3: 19 | E3: 3104 | F3: TRUE | G3: MEDIUM
A4: P1002 | B4: SSD | C4: Supplier 15 | D4: 11 | E4: 446.4 | F4: TRUE | G4: LOW
A5: P1003 | B5: SSD | C5: Supplier 9 | D5: 10 | E5: 513.6 | F5: TRUE | G5: LOW
A6: P1004 | B6: SSD | C6: Supplier 11 | D6: 14 | E6: 441.6 | F6: TRUE | G6: LOW
A7: P1005 | B7: NIC Card | C7: Supplier 5 | D7: 11 | E7: 200.2 | F7: TRUE | G7: MEDIUM
A8: P1006 | B8: NIC Card | C8: Supplier 10 | D8: 8 | E8: 209 | F8: TRUE | G8: MEDIUM
A9: P1007 | B9: DIMM | C9: Supplier 14 | D9: 10 | E9: 99.75 | F9: TRUE | G9: LOW
A10: P1008 | B10: DIMM | C10: Supplier 11 | D10: 10 | E10: 90.25 | F10: TRUE | G10: LOW
A11: P1009 | B11: DIMM | C11: Supplier 15 | D11: 11 | E11: 102.6 | F11: TRUE | G11: LOW
A12: P1010 | B12: Chassis | C12: Supplier 8 | D12: 15 | E12: 816 | F12: TRUE | G12: MEDIUM
A13: P1011 | B13: Chassis | C13: Supplier 7 | D13: 16 | E13: 824.5 | F13: TRUE | G13: MEDIUM
... A21: P1019 | B21: Cable Kit | C21: Supplier 16 | D21: 6 | E21: 45.36 | F21: TRUE | G21: MEDIUM

Sheet Demand_Forecast
A1: Week | B1: Program | C1: Part_Name | D1: Forecast_Qty | E1: Actual_Demand | F1: Variance | G1: Variance_Pct
A2: 2025-01-06 | B2: Program A | C2: GPU | D2: 65 | E2: 85 | F2: 20 | G2: 30.8
A3: 2025-01-13 | B3: Program A | C3: GPU | D3: 67 | E3: 65 | F3: -2 | G3: -3
A4: 2025-01-20 | B4: Program A | C4: GPU | D4: 78 | E4: 90 | F4: 12 | G4: 15.4
A5: 2025-01-27 | B5: Program A | C5: GPU | D5: 76 | E5: 66 | F5: -10 | G5: -13.2
A6: 2025-02-03 | B6: Program A | C6: GPU | D6: 74 | E6: 87 | F6: 13 | G6: 17.6
A7: 2025-02-10 | B7: Program A | C7: GPU | D7: 88 | E7: 104 | F7: 16 | G7: 18.2
A8: 2025-02-17 | B8: Program A | C8: GPU | D8: 92 | E8: 102 | F8: 10 | G8: 10.9
A9: 2025-02-24 | B9: Program A | C9: GPU | D9: 87 | E9: 87 | F9: 0 | G9: 0
A10: 2025-03-03 | B10: Program A | C10: GPU | D10: 98 | E10: 76 | F10: -22 | G10: -22.4
A11: 2025-03-10 | B11: Program A | C11: GPU | D11: 91 | E11: 102 | F11: 11 | G11: 12.1
A12: 2025-03-17 | B12: Program A | C12: GPU | D12: 101 | E12: 106 | F12: 5 | G12: 5
A13: 2025-03-24 | B13: Program A | C13: GPU | D13: 91 | E13: 106 | F13: 15 | G13: 16.5
... A1561: 2025-12-29 | B1561: Program E | C1561: Power Supply | D1561: 156 | E1561: 158 | F1561: 2 | G1561: 1.3

Sheet Inventory_Coverage
A1: Part_ID | B1: Part_Name | C1: Supplier | D1: Region | E1: On_Hand_Units | F1: On_Order_Units | G1: Weekly_Burn_Rate | H1: Coverage_Weeks | I1: Reorder_Point_Wks | J1: Below_Reorder | K1: Shortage_Risk
A2: P1000 | B2: GPU | C2: Supplier 13 | D2: NAM | E2: 213 | F2: 63 | G2: 18 | H2: 15.3 | I2: 21 | J2: TRUE | K2: LOW
A3: P1000 | B3: GPU | C3: Supplier 13 | D3: EMEA | E3: 133 | F3: 190 | G3: 77 | H3: 4.2 | I3: 21 | J3: TRUE | K3: HIGH
A4: P1000 | B4: GPU | C4: Supplier 13 | D4: APJ | E4: 314 | F4: 228 | G4: 37 | H4: 14.6 | I4: 21 | J4: TRUE | K4: LOW
A5: P1000 | B5: GPU | C5: Supplier 13 | D5: BRH | E5: 455 | F5: 242 | G5: 59 | H5: 11.8 | I5: 21 | J5: TRUE | K5: MEDIUM
A6: P1001 | B6: GPU | C6: Supplier 1 | D6: NAM | E6: 186 | F6: 83 | G6: 48 | H6: 5.6 | I6: 21 | J6: TRUE | K6: HIGH
A7: P1001 | B7: GPU | C7: Supplier 1 | D7: EMEA | E7: 393 | F7: 46 | G7: 51 | H7: 8.6 | I7: 21 | J7: TRUE | K7: MEDIUM
A8: P1001 | B8: GPU | C8: Supplier 1 | D8: APJ | E8: 24 | F8: 197 | G8: 21 | H8: 10.5 | I8: 21 | J8: TRUE | K8: MEDIUM
A9: P1001 | B9: GPU | C9: Supplier 1 | D9: BRH | E9: 93 | F9: 292 | G9: 42 | H9: 9.2 | I9: 21 | J9: TRUE | K9: MEDIUM
A10: P1002 | B10: SSD | C10: Supplier 15 | D10: NAM | E10: 448 | F10: 113 | G10: 43 | H10: 13 | I10: 13 | J10: FALSE | K10: LOW
A11: P1002 | B11: SSD | C11: Supplier 15 | D11: EMEA | E11: 356 | F11: 105 | G11: 49 | H11: 9.4 | I11: 13 | J11: TRUE | K11: MEDIUM
A12: P1002 | B12: SSD | C12: Supplier 15 | D12: APJ | E12: 343 | F12: 209 | G12: 80 | H12: 6.9 | I12: 13 | J12: TRUE | K12: HIGH
A13: P1002 | B13: SSD | C13: Supplier 15 | D13: BRH | E13: 20 | F13: 4 | G13: 75 | H13: 0.3 | I13: 13 | J13: TRUE | K13: CRITICAL
... A81: P1019 | B81: Cable Kit | C81: Supplier 16 | D81: BRH | E81: 365 | F81: 4 | G81: 53 | H81: 7 | I81: 8 | J81: TRUE | K81: HIGH

Sheet Purchase_Orders
A1: PO_Number | B1: Part_ID | C1: Part_Name | D1: Supplier | E1: Factory | F1: Region | G1: PO_Date | H1: Need_By_Date | I1: Expected_Date | J1: Quantity_Ordered | K1: Unit_Cost_USD | L1: Total_Value_USD | M1: Status | N1: On_Time | O1: Days_Late
A2: PO-10000 | B2: P1000 | C2: GPU | D2: Supplier 13 | E2: Factory 2 | F2: BRH | G2: 2025-09-29 | H2: 2026-02-09 | I2: 2026-02-13 | J2: 383 | K2: 2976 | L2: 1139808 | M2: Open | N2: TRUE | O2: 0
A3: PO-10001 | B3: P1019 | C3: Cable Kit | D3: Supplier 16 | E3: Factory 2 | F3: BRH | G3: 2025-09-24 | H3: 2025-11-05 | I3: 2025-11-01 | J3: 169 | K3: 45.36 | L3: 7665.84 | M3: Open | N3: TRUE | O3: 0
A4: PO-10002 | B4: P1010 | C4: Chassis | D4: Supplier 8 | E4: Factory 4 | F4: NAM | G4: 2025-04-17 | H4: 2025-07-31 | I4: 2025-07-30 | J4: 292 | K4: 816 | L4: 238272 | M4: Open | N4: TRUE | O4: 0
A5: PO-10003 | B5: P1000 | C5: GPU | D5: Supplier 13 | E5: Factory 4 | F5: APJ | G5: 2025-06-06 | H5: 2025-10-17 | I5: 2025-11-10 | J5: 279 | K5: 2976 | L5: 830304 | M5: Delayed | N5: FALSE | O5: 24
A6: PO-10004 | B6: P1005 | C6: NIC Card | D6: Supplier 5 | E6: Factory 4 | F6: EMEA | G6: 2025-06-24 | H6: 2025-09-09 | I6: 2025-09-04 | J6: 368 | K6: 200.2 | L6: 73673.6 | M6: Open | N6: TRUE | O6: 0
A7: PO-10005 | B7: P1003 | C7: SSD | D7: Supplier 9 | E7: Factory 5 | F7: NAM | G7: 2025-09-15 | H7: 2025-11-24 | I7: 2025-12-03 | J7: 286 | K7: 513.6 | L7: 146889.6 | M7: Delayed | N7: FALSE | O7: 9
A8: PO-10006 | B8: P1013 | C8: Power Supply | D8: Supplier 2 | E8: Factory 2 | F8: NAM | G8: 2025-05-17 | H8: 2025-07-19 | I8: 2025-07-21 | J8: 176 | K8: 187.25 | L8: 32956 | M8: In Transit | N8: TRUE | O8: 0
A9: PO-10007 | B9: P1017 | C9: LCD Bezel | D9: Supplier 8 | E9: Factory 2 | F9: BRH | G9: 2025-02-26 | H9: 2025-05-28 | I9: 2025-05-23 | J9: 173 | K9: 59.8 | L9: 10345.4 | M9: In Transit | N9: TRUE | O9: 0
A10: PO-10008 | B10: P1017 | C10: LCD Bezel | D10: Supplier 8 | E10: Factory 4 | F10: APJ | G10: 2025-03-06 | H10: 2025-06-05 | I10: 2025-06-13 | J10: 29 | K10: 59.8 | L10: 1734.2 | M10: Delayed | N10: FALSE | O10: 8
A11: PO-10009 | B11: P1004 | C11: SSD | D11: Supplier 11 | E11: Factory 3 | F11: EMEA | G11: 2025-06-23 | H11: 2025-09-29 | I11: 2025-10-01 | J11: 343 | K11: 441.6 | L11: 151468.8 | M11: In Transit | N11: TRUE | O11: 0
A12: PO-10010 | B12: P1002 | C12: SSD | D12: Supplier 15 | E12: Factory 1 | F12: NAM | G12: 2025-06-30 | H12: 2025-09-15 | I12: 2025-09-16 | J12: 229 | K12: 446.4 | L12: 102225.6 | M12: In Transit | N12: TRUE | O12: 0
A13: PO-10011 | B13: P1014 | C13: Custom NIC | D13: Supplier 5 | E13: Factory 4 | F13: APJ | G13: 2025-09-07 | H13: 2026-01-11 | I13: 2026-01-16 | J13: 110 | K13: 397.7 | L13: 43747 | M13: Open | N13: TRUE | O13: 0
... A351: PO-10349 | B351: P1000 | C351: GPU | D351: Supplier 13 | E351: Factory 1 | F351: NAM | G351: 2025-09-11 | H351: 2026-01-22 | I351: 2026-02-14 | J351: 64 | K351: 2976 | L351: 190464 | M351: Delayed | N351: FALSE | O351: 23

Sheet NPI_Program_Tracker
A1: Program | B1: Region | C1: Milestone | D1: Planned_Date | E1: Actual_Date | F1: Status | G1: Days_Variance | H1: Multi_Source_Pct | I1: Clean_Launch
A2: Program A | B2: NAM | C2: Design Freeze | D2: 2025-01-15 | E2: 2025-01-21 | F2: Complete | G2: 6 | H2: 92 | I2: TRUE
A3: Program A | B3: NAM | C3: Pilot Build | D3: 2025-02-12 | E3: 2025-02-14 | F3: Complete | G3: 2 | H3: 92 | I3: TRUE
A4: Program A | B4: NAM | C4: Factory Readiness | D4: 2025-03-12 | E4: 2025-03-09 | F4: Complete | G4: -3 | H4: 88 | I4: TRUE
A5: Program A | B5: NAM | C5: Material in Hub | D5: 2025-04-09 | E5: 2025-04-11 | F5: In Progress | G5: 2 | H5: 90 | I5: TRUE
A6: Program A | B6: NAM | C6: RTS / Launch | D6: 2025-05-07 | F6: At Risk | H6: 90 | I6: TRUE
A7: Program A | B7: NAM | C7: Post-Launch Review | D7: 2025-06-04 | F7: Not Started | H7: 90 | I7: TRUE
A8: Program A | B8: EMEA | C8: Design Freeze | D8: 2025-01-15 | E8: 2025-01-19 | F8: Complete | G8: 4 | H8: 88 | I8: TRUE
A9: Program A | B9: EMEA | C9: Pilot Build | D9: 2025-02-12 | E9: 2025-02-17 | F9: Complete | G9: 5 | H9: 93 | I9: TRUE
A10: Program A | B10: EMEA | C10: Factory Readiness | D10: 2025-03-12 | E10: 2025-03-10 | F10: Complete | G10: -2 | H10: 86 | I10: TRUE
A11: Program A | B11: EMEA | C11: Material in Hub | D11: 2025-04-09 | E11: 2025-04-11 | F11: In Progress | G11: 2 | H11: 87 | I11: TRUE
A12: Program A | B12: EMEA | C12: RTS / Launch | D12: 2025-05-07 | F12: At Risk | H12: 91 | I12: TRUE
A13: Program A | B13: EMEA | C13: Post-Launch Review | D13: 2025-06-04 | F13: Not Started | H13: 92 | I13: TRUE
A14: Program A | B14: APJ | C14: Design Freeze | D14: 2025-01-15 | E14: 2025-01-10 | F14: Complete | G14: -5 | H14: 85 | I14: TRUE
A15: Program A | B15: APJ | C15: Pilot Build | D15: 2025-02-12 | E15: 2025-02-18 | F15: Complete | G15: 6 | H15: 87 | I15: FALSE
A16: Program A | B16: APJ | C16: Factory Readiness | D16: 2025-03-12 | E16: 2025-03-09 | F16: Complete | G16: -3 | H16: 83 | I16: FALSE
A17: Program A | B17: APJ | C17: Material in Hub | D17: 2025-04-09 | E17: 2025-04-09 | F17: In Progress | G17: 0 | H17: 88 | I17: TRUE
A18: Program A | B18: APJ | C18: RTS / Launch | D18: 2025-05-07 | F18: At Risk | H18: 90 | I18: TRUE
A19: Program A | B19: APJ | C19: Post-Launch Review | D19: 2025-06-04 | F19: Not Started | H19: 88 | I19: TRUE
A20: Program A | B20: BRH | C20: Design Freeze | D20: 2025-01-15 | E20: 2025-01-10 | F20: Complete | G20: -5 | H20: 84 | I20: TRUE
A21: Program A | B21: BRH | C21: Pilot Build | D21: 2025-02-12 | E21: 2025-02-05 | F21: Complete | G21: -7 | H21: 80 | I21: TRUE
A22: Program A | B22: BRH | C22: Factory Readiness | D22: 2025-03-12 | E22: 2025-03-12 | F22: Complete | G22: 0 | H22: 82 | I22: TRUE
A23: Program A | B23: BRH | C23: Material in Hub | D23: 2025-04-09 | E23: 2025-04-10 | F23: In Progress | G23: 1 | H23: 76 | I23: FALSE
A24: Program A | B24: BRH | C24: RTS / Launch | D24: 2025-05-07 | F24: At Risk | H24: 81 | I24: TRUE
A25: Program A | B25: BRH | C25: Post-Launch Review | D25: 2025-06-04 | F25: Not Started | H25: 80 | I25: TRUE
A26: Program B | B26: NAM | C26: Design Freeze | D26: 2025-01-15 | E26: 2025-01-12 | F26: Complete | G26: -3 | H26: 89 | I26: TRUE
A27: Program B | B27: NAM | C27: Pilot Build | D27: 2025-02-12 | E27: 2025-02-14 | F27: Complete | G27: 2 | H27: 94 | I27: TRUE
A28: Program B | B28: NAM | C28: Factory Readiness | D28: 2025-03-12 | E28: 2025-03-15 | F28: Complete | G28: 3 | H28: 91 | I28: TRUE
A29: Program B | B29: NAM | C29: Material in Hub | D29: 2025-04-09 | E29: 2025-04-11 | F29: In Progress | G29: 2 | H29: 91 | I29: TRUE
A30: Program B | B30: NAM | C30: RTS / Launch | D30: 2025-05-07 | F30: At Risk | H30: 90 | I30: TRUE
A31: Program B | B31: NAM | C31: Post-Launch Review | D31: 2025-06-04 | F31: Not Started | H31: 88 | I31: TRUE
A32: Program B | B32: EMEA | C32: Design Freeze | D32: 2025-01-15 | E32: 2025-01-08 | F32: Complete | G32: -7 | H32: 91 | I32: FALSE
A33: Program B | B33: EMEA | C33: Pilot Build | D33: 2025-02-12 | E33: 2025-02-06 | F33: Complete | G33: -6 | H33: 92 | I33: TRUE
A34: Program B | B34: EMEA | C34: Factory Readiness | D34: 2025-03-12 | E34: 2025-03-16 | F34: Complete | G34: 4 | H34: 89 | I34: TRUE
A35: Program B | B35: EMEA | C35: Material in Hub | D35: 2025-04-09 | E35: 2025-04-02 | F35: In Progress | G35: -7 | H35: 85 | I35: TRUE
A36: Program B | B36: EMEA | C36: RTS / Launch | D36: 2025-05-07 | F36: At Risk | H36: 88 | I36: TRUE
A37: Program B | B37: EMEA | C37: Post-Launch Review | D37: 2025-06-04 | F37: Not Started | H37: 86 | I37: TRUE
A38: Program B | B38: APJ | C38: Design Freeze | D38: 2025-01-15 | E38: 2025-01-09 | F38: Complete | G38: -6 | H38: 83 | I38: TRUE
A39: Program B | B39: APJ | C39: Pilot Build | D39: 2025-02-12 | E39: 2025-02-07 | F39: Complete | G39: -5 | H39: 88 | I39: TRUE
A40: Program B | B40: APJ | C40: Factory Readiness | D40: 2025-03-12 | E40: 2025-03-19 | F40: Complete | G40: 7 | H40: 84 | I40: TRUE
...

Sheet Supplier_Scorecard
A1: Supplier | B1: On_Time_Delivery_Pct | C1: Quality_PPM | D1: Lead_Time_Adherence_Pct | E1: Avg_Days_Late | F1: Open_POs | G1: Total_Spend_USD_M | H1: Single_Source_Parts | I1: Risk_Rating
A2: Supplier 4 | B2: 95.1 | C2: 1906 | D2: 69.3 | E2: 13.3 | F2: 37 | G2: 5.58 | H2: 0 | I2: MEDIUM
A3: Supplier 16 | B3: 85.4 | C3: 340 | D3: 94 | E3: 13 | F3: 40 | G3: 16.57 | H3: 3 | I3: LOW
A4: Supplier 1 | B4: 91.4 | C4: 1384 | D4: 74.7 | E4: 2 | F4: 17 | G4: 3.47 | H4: 3 | I4: LOW
A5: Supplier 7 | B5: 81.8 | C5: 953 | D5: 70.1 | E5: 10.5 | F5: 6 | G5: 25.02 | H5: 1 | I5: LOW
A6: Supplier 13 | B6: 96.1 | C6: 1913 | D6: 73.2 | E6: 6.7 | F6: 32 | G6: 20.38 | H6: 2 | I6: MEDIUM
A7: Supplier 14 | B7: 77.3 | C7: 571 | D7: 68.9 | E7: 10.2 | F7: 20 | G7: 4.51 | H7: 3 | I7: MEDIUM
A8: Supplier 10 | B8: 82.9 | C8: 1457 | D8: 74.4 | E8: 5.3 | F8: 13 | G8: 22.28 | H8: 4 | I8: LOW
A9: Supplier 12 | B9: 87 | C9: 990 | D9: 70.5 | E9: 15.4 | F9: 34 | G9: 24.25 | H9: 1 | I9: HIGH
A10: Supplier 11 | B10: 84.3 | C10: 1945 | D10: 76.1 | E10: 13.1 | F10: 18 | G10: 7.54 | H10: 3 | I10: HIGH
A11: Supplier 6 | B11: 77.8 | C11: 660 | D11: 94.5 | E11: 16.2 | F11: 29 | G11: 27.46 | H11: 0 | I11: MEDIUM
A12: Supplier 9 | B12: 91.1 | C12: 2115 | D12: 69 | E12: 9.6 | F12: 33 | G12: 22.82 | H12: 0 | I12: MEDIUM
A13: Supplier 15 | B13: 84.9 | C13: 390 | D13: 84.2 | E13: 0.2 | F13: 29 | G13: 26.64 | H13: 1 | I13: MEDIUM
... A17: Supplier 2 | B17: 91.6 | C17: 898 | D17: 90.8 | E17: 1.5 | F17: 24 | G17: 20.81 | H17: 0 | I17: HIGH
